<?xml version="1.0" encoding="utf-8"?>
<!-- This URDF was automatically created by SolidWorks to URDF Exporter! Originally created by Stephen Brawner (brawner@gmail.com) 
     Commit Version: 1.6.0-1-g15f4949  Build Version: 1.6.7594.29634
     For more information, please see http://wiki.ros.org/sw_urdf_exporter -->
<robot
  name="arm">
  <link
    name="base_cylinder">
    <inertial>
      <origin
        xyz="0.00089876 -6.4996E-19 0.021715"
        rpy="0 0 0" />
      <mass
        value="0.36165" />
      <inertia
        ixx="0.00049389"
        ixy="2.4965E-23"
        ixz="1.7043E-22"
        iyy="0.00049373"
        iyz="-2.3302E-20"
        izz="0.0008312" />
    </inertial>
    <visual>
      <origin
        xyz="0 0 0"
        rpy="0 0 0" />
      <geometry>
        <mesh
          filename="package://manipulator_v1/manipulator_description/arm/meshes/base_cylinder.STL" />
      </geometry>
      <material
        name="">
        <color
          rgba="0.79216 0.81961 0.93333 1" />
      </material>
    </visual>
    <collision>
      <origin
        xyz="0 0 0"
        rpy="0 0 0" />
      <geometry>
        <mesh
          filename="package://manipulator_v1/manipulator_description/arm/meshes/base_cylinder.STL" />
      </geometry>
    </collision>
  </link>
  <link
    name="num_base">
    <inertial>
      <origin
        xyz="-7.557E-15 5.6181E-16 0.1"
        rpy="0 0 0" />
      <mass
        value="0.3953" />
      <inertia
        ixx="0.0015909"
        ixy="-6.5339E-07"
        ixz="-2.7188E-22"
        iyy="0.0015463"
        iyz="5.3533E-20"
        izz="0.00050191" />
    </inertial>
    <visual>
      <origin
        xyz="0 0 0"
        rpy="0 0 0" />
      <geometry>
        <mesh
          filename="package://manipulator_v1/manipulator_description/arm/meshes/num_base.STL" />
      </geometry>
      <material
        name="">
        <color
          rgba="0.79216 0.81961 0.93333 1" />
      </material>
    </visual>
    <collision>
      <origin
        xyz="0 0 0"
        rpy="0 0 0" />
      <geometry>
        <mesh
          filename="package://manipulator_v1/manipulator_description/arm/meshes/num_base.STL" />
      </geometry>
    </collision>
  </link>
  <joint
    name="num_base_joint"
    type="continuous">
    <origin
      xyz="0 0 0.01"
      rpy="0 0 0" />
    <parent
      link="base_cylinder" />
    <child
      link="num_base" />
    <axis
      xyz="0 0 1" />
  </joint>
  <link
    name="num_piston">
    <inertial>
      <origin
        xyz="-1.9338E-05 -0.0013215 0.068891"
        rpy="0 0 0" />
      <mass
        value="0.41599" />
      <inertia
        ixx="0.00078298"
        ixy="2.1911E-07"
        ixz="5.3898E-07"
        iyy="0.00079795"
        iyz="3.6832E-05"
        izz="0.00021545" />
    </inertial>
    <visual>
      <origin
        xyz="0 0 0"
        rpy="0 0 0" />
      <geometry>
        <mesh
          filename="package://manipulator_v1/manipulator_description/arm/meshes/num_piston.STL" />
      </geometry>
      <material
        name="">
        <color
          rgba="0.79216 0.81961 0.93333 1" />
      </material>
    </visual>
    <collision>
      <origin
        xyz="0 0 0"
        rpy="0 0 0" />
      <geometry>
        <mesh
          filename="package://manipulator_v1/manipulator_description/arm/meshes/num_piston.STL" />
      </geometry>
    </collision>
  </link>
  <joint
    name="num_piston_joint"
    type="prismatic">
    <origin
      xyz="0 0 0.2"
      rpy="0 0 0" />
    <parent
      link="num_base" />
    <child
      link="num_piston" />
    <axis
      xyz="0 0 1" />
    <limit
      lower="0"
      upper="0.5"
      effort="10"
      velocity="3" />
  </joint>
  <link
    name="mid_link">
    <inertial>
      <origin
        xyz="0.016619 0.015082 0.24196"
        rpy="0 0 0" />
      <mass
        value="0.87256" />
      <inertia
        ixx="0.018828"
        ixy="-7.4446E-07"
        ixz="-0.0012559"
        iyy="0.019081"
        iyz="-4.7149E-05"
        izz="0.00039149" />
    </inertial>
    <visual>
      <origin
        xyz="0 0 0"
        rpy="0 0 0" />
      <geometry>
        <mesh
          filename="package://manipulator_v1/manipulator_description/arm/meshes/mid_link.STL" />
      </geometry>
      <material
        name="">
        <color
          rgba="0.79216 0.81961 0.93333 1" />
      </material>
    </visual>
    <collision>
      <origin
        xyz="0 0 0"
        rpy="0 0 0" />
      <geometry>
        <mesh
          filename="package://manipulator_v1/manipulator_description/arm/meshes/mid_link.STL" />
      </geometry>
    </collision>
  </link>
  <joint
    name="mid_link_joint"
    type="revolute">
    <origin
      xyz="-0.00087791 -0.059994 0.13589"
      rpy="0 0 0" />
    <parent
      link="num_piston" />
    <child
      link="mid_link" />
    <axis
      xyz="-0.014632 -0.99989 0" />
    <limit
      lower="-2.267"
      upper="0.697"
      effort="5"
      velocity="3" />
  </joint>
  <link
    name="end_link">
    <inertial>
      <origin
        xyz="0.013311 -0.015196 0.11712"
        rpy="0 0 0" />
      <mass
        value="0.45387" />
      <inertia
        ixx="0.002689"
        ixy="1.869E-06"
        ixz="-0.00029197"
        iyy="0.0028167"
        iyz="4.2725E-06"
        izz="0.00019068" />
    </inertial>
    <visual>
      <origin
        xyz="0 0 0"
        rpy="0 0 0" />
      <geometry>
        <mesh
          filename="package://manipulator_v1/manipulator_description/arm/meshes/end_link.STL" />
      </geometry>
      <material
        name="">
        <color
          rgba="0.79216 0.81961 0.93333 1" />
      </material>
    </visual>
    <collision>
      <origin
        xyz="0 0 0"
        rpy="0 0 0" />
      <geometry>
        <mesh
          filename="package://manipulator_v1/manipulator_description/arm/meshes/end_link.STL" />
      </geometry>
    </collision>
  </link>
  <joint
    name="end_link_joint"
    type="revolute">
    <origin
      xyz="0.032974 0.059524 0.4737"
      rpy="0 0 0" />
    <parent
      link="mid_link" />
    <child
      link="end_link" />
    <axis
      xyz="0.014632 0.99989 0" />
    <limit
      lower="0"
      upper="6.28"
      effort="2"
      velocity="3" />
  </joint>
  
    
   <transmission name="base_transmission">
      <type>transmission_interface/SimpleTransmission</type>
      <joint name="num_base_joint">
            <hardwareInterface>hardware_interface/PositionJointInterface</hardwareInterface>
      </joint>      
    <actuator name="actuator1">
        <mechanicalReduction>1</mechanicalReduction>
    </actuator>
  </transmission>
  
    <transmission name="prismatic_trnsmission">
      <type>transmission_interface/SimpleTransmission</type>
      <joint name="num_piston_joint">
            <hardwareInterface>hardware_interface/PositionJointInterface</hardwareInterface>
      </joint>      
    <actuator name="actuator2">
        <mechanicalReduction>1</mechanicalReduction>
    </actuator>
  </transmission>
  
    <transmission name="lin_transmission1">
      <type>transmission_interface/SimpleTransmission</type>
      <joint name="mid_link_joint">
            <hardwareInterface>hardware_interface/PositionJointInterface</hardwareInterface>
      </joint>      
    <actuator name="actuator3">
        <mechanicalReduction>1</mechanicalReduction>
    </actuator>
  </transmission>
  
    <transmission name="lin_transmission2">
      <type>transmission_interface/SimpleTransmission</type>
      <joint name="end_link_joint">
            <hardwareInterface>hardware_interface/PositionJointInterface</hardwareInterface>
      </joint>      
    <actuator name="actuator4">
        <mechanicalReduction>1</mechanicalReduction>
    </actuator>
  </transmission>
  
  <!-- ros_controll_plugin -->
  <gazebo>
      <plugin name="gazebo_ros_control" filename="libgazebo_ros_control.so">
          <robotNamespace>/arm</robotNamespace> 
          <robotSimType>gazebo_ros_control/DefaultRobotHWSim</robotSimType> 
      </plugin>
  </gazebo>
  
  
</robot>
