<?xml version="1.0" encoding="utf-8"?>
<!-- This URDF was automatically created by SolidWorks to URDF Exporter! Originally created by Stephen Brawner (brawner@gmail.com) 
     Commit Version: 1.6.0-1-g15f4949  Build Version: 1.6.7594.29634
     For more information, please see http://wiki.ros.org/sw_urdf_exporter -->
<robot
  name="arm">
    
    <link name="world"/>

  <joint name="fixed" type="fixed">
    <parent link="world"/>
    <child link="man_base"/>
  </joint>
  
  <link
    name="man_base">
    <inertial>
      <origin
        xyz="0.062122 2.7756E-17 0.040868"
        rpy="0 0 0" />
      <mass
        value="2.5319" />
      <inertia
        ixx="0.019316"
        ixy="-1.0584E-18"
        ixz="-0.0073609"
        iyy="0.039139"
        iyz="-5.4676E-20"
        izz="0.025853" />
    </inertial>
    <visual>
      <origin
        xyz="0 0 0"
        rpy="0 0 0" />
      <geometry>
        <mesh
          filename="package://manipulator_v1/manipulator_description/arm/meshes/man_base.STL" />
      </geometry>
      <material
        name="">
        <color
          rgba="0.96078 0.96078 0.96471 1" />
      </material>
    </visual>
    <collision>
      <origin
        xyz="0 0 0"
        rpy="0 0 0" />
      <geometry>
        <mesh
          filename="package://manipulator_v1/manipulator_description/arm/meshes/man_base.STL" />
      </geometry>
    </collision>
  </link>
  
  <link
    name="lin_link">
    <inertial>
      <origin
        xyz="0.00058824 6.8403E-10 0.14981"
        rpy="0 0 0" />
      <mass
        value="0.48064" />
      <inertia
        ixx="0.0036268"
        ixy="-1.1217E-12"
        ixz="-3.3983E-05"
        iyy="0.0036388"
        iyz="-4.0231E-11"
        izz="0.00013762" />
    </inertial>
    <visual>
      <origin
        xyz="0 0 0"
        rpy="0 0 0" />
      <geometry>
        <mesh
          filename="package://manipulator_v1/manipulator_description/arm/meshes/lin_link.STL" />
      </geometry>
      <material
        name="">
        <color
          rgba="0.96078 0.96078 0.96471 1" />
      </material>
    </visual>
    <collision>
      <origin
        xyz="0 0 0"
        rpy="0 0 0" />
      <geometry>
        <mesh
          filename="package://manipulator_v1/manipulator_description/arm/meshes/lin_link.STL" />
      </geometry>
    </collision>
  </link>

  <joint
        name="base_joint"
        type="prismatic">
        <origin
        xyz="0.1166 0 0.225"
        rpy="0 0 0" />
        <parent
        link="man_base" />
        <child
        link="lin_link" />
        <axis
        xyz="0 0 1" />
        <limit
        lower="0"
        upper="0.15"
        effort="500"
        velocity="0.1" />
    </joint>
  
  <link
    name="mid_link">
    <inertial>
      <origin
        xyz="0.00034363 -0.26293 -4.3005E-05"
        rpy="0 0 0" />
      <mass
        value="0.82251" />
      <inertia
        ixx="0.01817"
        ixy="6.2324E-05"
        ixz="-1.2149E-08"
        iyy="0.00022901"
        iyz="8.5848E-06"
        izz="0.018181" />
    </inertial>
    <visual>
      <origin
        xyz="0 0 0"
        rpy="0 0 0" />
      <geometry>
        <mesh
          filename="package://manipulator_v1/manipulator_description/arm/meshes/mid_link.STL" />
      </geometry>
      <material
        name="">
        <color
          rgba="0.96078 0.96078 0.96471 1" />
      </material>
    </visual>
    <collision>
      <origin
        xyz="0 0 0"
        rpy="0 0 0" />
      <geometry>
        <mesh
          filename="package://manipulator_v1/manipulator_description/arm/meshes/mid_link.STL" />
      </geometry>
    </collision>
  </link>
  <joint
    name="rev_joint1"
    type="revolute">
    <origin
      xyz="0.04 0.02 0.265"
      rpy="0 0 0" />
    <parent
      link="lin_link" />
    <child
      link="mid_link" />
    <axis
      xyz="1 0 0" />
    <limit
      lower="-2.267"
      upper="0.697"
      effort="200"
      velocity="0.1" />
  </joint>
  <link
    name="end_link">
    <inertial>
      <origin
        xyz="-7.0543E-08 -0.00028367 0.14147"
        rpy="0 0 0" />
      <mass
        value="0.43723" />
      <inertia
        ixx="0.0027717"
        ixy="-1.4807E-11"
        ixz="-1.5074E-09"
        iyy="0.0027684"
        iyz="9.0656E-06"
        izz="0.00011819" />
    </inertial>
    <visual>
      <origin
        xyz="0 0 0"
        rpy="0 0 0" />
      <geometry>
        <mesh
          filename="package://manipulator_v1/manipulator_description/arm/meshes/end_link.STL" />
      </geometry>
      <material
        name="">
        <color
          rgba="0.96078 0.96078 0.96471 1" />
      </material>
    </visual>
    <collision>
      <origin
        xyz="0 0 0"
        rpy="0 0 0" />
      <geometry>
        <mesh
          filename="package://manipulator_v1/manipulator_description/arm/meshes/end_link.STL" />
      </geometry>
    </collision>
  </link>
  <joint
    name="rev_joint2"
    type="revolute">
    <origin
      xyz="0.04 -0.485 -0.02"
      rpy="0 0 0" />
    <parent
      link="mid_link" />
    <child
      link="end_link" />
    <axis
      xyz="1 0 0" />
    <limit
      lower="0"
      upper="6.28"
      effort="100"
      velocity="0.1" />
  </joint>
  
   <transmission name="lin_tran_base">
      <type>transmission_interface/SimpleTransmission</type>
      <joint name="base_joint">
            <hardwareInterface>hardware_interface/EffortJointInterface</hardwareInterface>
      </joint>      
    <actuator name="lin_actuator">
        <mechanicalReduction>1</mechanicalReduction>
    </actuator>
  </transmission>
  
    <transmission name="lin_tran_rev1">
      <type>transmission_interface/SimpleTransmission</type>
      <joint name="rev_joint1">
            <hardwareInterface>hardware_interface/EffortJointInterface</hardwareInterface>
      </joint>      
    <actuator name="rev_actuator1">
        <mechanicalReduction>1</mechanicalReduction>
    </actuator>
  </transmission>
  
    <transmission name="lin_tran_rev2">
      <type>transmission_interface/SimpleTransmission</type>
      <joint name="rev_joint2">
            <hardwareInterface>hardware_interface/EffortJointInterface</hardwareInterface>
      </joint>      
    <actuator name="rev_actuator2">
        <mechanicalReduction>1</mechanicalReduction>
    </actuator>
  </transmission>
  
  <!-- ros_controll_plugin -->
  <gazebo>
      <plugin name="gazebo_ros_control" filename="libgazebo_ros_control.so">
          <robotNamespace>/arm</robotNamespace>
      </plugin>
  </gazebo>
  
  
</robot>
